START TEST PREP
Wed Feb  2 14:53:40 EST 2022
Traceback (most recent call last):
  File "/Users/kprovost/opt/anaconda3/bin/vak", line 8, in <module>
    sys.exit(main())
  File "/Users/kprovost/opt/anaconda3/lib/python3.8/site-packages/vak/__main__.py", line 43, in main
    cli(command=args.command,
  File "/Users/kprovost/opt/anaconda3/lib/python3.8/site-packages/vak/cli/cli.py", line 19, in cli
    prep(toml_path=config_file)
  File "/Users/kprovost/opt/anaconda3/lib/python3.8/site-packages/vak/cli/prep.py", line 53, in prep
    cfg = config.parse.from_toml(toml_path)
  File "/Users/kprovost/opt/anaconda3/lib/python3.8/site-packages/vak/config/parse.py", line 110, in from_toml
    config_dict[section_name.lower()] = section_parser(config_toml, toml_path)
  File "/Users/kprovost/opt/anaconda3/lib/python3.8/site-packages/vak/config/predict.py", line 127, in parse_predict_config
    return PredictConfig(**predict_section)
  File "<attrs generated init vak.config.predict.PredictConfig>", line 19, in __init__
  File "/Users/kprovost/opt/anaconda3/lib/python3.8/site-packages/attr/validators.py", line 192, in __call__
    self.validator(inst, attr, value)
  File "/Users/kprovost/opt/anaconda3/lib/python3.8/site-packages/vak/config/validators.py", line 22, in is_a_file
    raise FileNotFoundError(
FileNotFoundError: Value specified for csv_path of <class 'vak.config.predict.PredictConfig'> not recognized as a file:
/Users/kprovost/Documents/Postdoc_Working/JY_project/b17_prep_220202_144830.csv
START TEST
Wed Feb  2 14:53:44 EST 2022
Traceback (most recent call last):
  File "/Users/kprovost/opt/anaconda3/bin/vak", line 8, in <module>
    sys.exit(main())
  File "/Users/kprovost/opt/anaconda3/lib/python3.8/site-packages/vak/__main__.py", line 43, in main
    cli(command=args.command,
  File "/Users/kprovost/opt/anaconda3/lib/python3.8/site-packages/vak/cli/cli.py", line 28, in cli
    predict(toml_path=config_file)
  File "/Users/kprovost/opt/anaconda3/lib/python3.8/site-packages/vak/cli/predict.py", line 23, in predict
    cfg = config.parse.from_toml(toml_path)
  File "/Users/kprovost/opt/anaconda3/lib/python3.8/site-packages/vak/config/parse.py", line 110, in from_toml
    config_dict[section_name.lower()] = section_parser(config_toml, toml_path)
  File "/Users/kprovost/opt/anaconda3/lib/python3.8/site-packages/vak/config/predict.py", line 127, in parse_predict_config
    return PredictConfig(**predict_section)
  File "<attrs generated init vak.config.predict.PredictConfig>", line 19, in __init__
  File "/Users/kprovost/opt/anaconda3/lib/python3.8/site-packages/attr/validators.py", line 192, in __call__
    self.validator(inst, attr, value)
  File "/Users/kprovost/opt/anaconda3/lib/python3.8/site-packages/vak/config/validators.py", line 22, in is_a_file
    raise FileNotFoundError(
FileNotFoundError: Value specified for csv_path of <class 'vak.config.predict.PredictConfig'> not recognized as a file:
/Users/kprovost/Documents/Postdoc_Working/JY_project/b17_prep_220202_144830.csv
FINISHED TEST
Wed Feb  2 14:53:47 EST 2022
